Workbook
Name ElencoCalciatori: _Liste!$A$1:$A$479

Sheet Rosa 25
A1: PLANNER ROSA MANTRA 4-3-3 — PIANO BOMBER + GIOIELLI
A2: Target = piano di spesa; Offerta max = walk-away cap. Se paghi oltre target ma sotto cap, recupera la differenza su slot low cost/coppie.
A4: Budget totale | B4: 500 | D4: STATUS DATI: 28/08/2026 — PRE-CHIUSURA MERCATO Check finale obbligatorio il 02/09 per trasferimenti e ruoli Mantra.
A5: Spesa movimento | B5: =SUM(I11:I35)
A6: Spesa portieri | B6: =SUM(I40:I42)
A7: Spesa totale | B7: =B5+B6 | D7: GUARDRAIL: A + Pc = 272 crediti target (54,4% del budget). Il modello accetta top cari e finanzia il surplus con provincia, coppie e low cost.
A8: Residuo | B8: =B4-B7
A9: Posti rimasti | B9: =28-COUNTA(D11:D35)-COUNTA(D40:D42)
A10: # | B10: Profilo slot | C10: Target | D10: Nome | E10: Squadra | F10: R. Mantra | G10: Tit.% | H10: Offerta max | I10: Costo pagato | J10: Scost. max | K10: Strategia | L10: Note live
A11: 1 | B11: Dd 1 — TOP | C11: 18 | E11: =IFERROR(VLOOKUP($D11,'Lista calciatori'!$B$2:$AW$549,3,FALSE),"") | F11: =IFERROR(VLOOKUP($D11,'Lista calciatori'!$B$2:$AW$549,6,FALSE),"") | G11: =IFERROR(VLOOKUP($D11,'Lista calciatori'!$B$2:$AW$549,14,FALSE),"") | H11: =IFERROR(VLOOKUP($D11,'Lista calciatori'!$B$2:$AW$549,30,FALSE),"") | J11: =IF(OR(H11="",I11=""),"",H11-I11) | K11: =IFERROR(VLOOKUP($D11,'Lista calciatori'!$B$2:$AW$549,42,FALSE),"")
A12: 2 | B12: Dd 2 — TITOLARE | C12: 4 | E12: =IFERROR(VLOOKUP($D12,'Lista calciatori'!$B$2:$AW$549,3,FALSE),"") | F12: =IFERROR(VLOOKUP($D12,'Lista calciatori'!$B$2:$AW$549,6,FALSE),"") | G12: =IFERROR(VLOOKUP($D12,'Lista calciatori'!$B$2:$AW$549,14,FALSE),"") | H12: =IFERROR(VLOOKUP($D12,'Lista calciatori'!$B$2:$AW$549,30,FALSE),"") | J12: =IF(OR(H12="",I12=""),"",H12-I12) | K12: =IFERROR(VLOOKUP($D12,'Lista calciatori'!$B$2:$AW$549,42,FALSE),"")
A13: 3 | B13: Dd 3 — SCOMMESSA | C13: 2 | E13: =IFERROR(VLOOKUP($D13,'Lista calciatori'!$B$2:$AW$549,3,FALSE),"") | F13: =IFERROR(VLOOKUP($D13,'Lista calciatori'!$B$2:$AW$549,6,FALSE),"") | G13: =IFERROR(VLOOKUP($D13,'Lista calciatori'!$B$2:$AW$549,14,FALSE),"") | H13: =IFERROR(VLOOKUP($D13,'Lista calciatori'!$B$2:$AW$549,30,FALSE),"") | J13: =IF(OR(H13="",I13=""),"",H13-I13) | K13: =IFERROR(VLOOKUP($D13,'Lista calciatori'!$B$2:$AW$549,42,FALSE),"")
A14: 4 | B14: Ds 1 — TOP | C14: 18 | E14: =IFERROR(VLOOKUP($D14,'Lista calciatori'!$B$2:$AW$549,3,FALSE),"") | F14: =IFERROR(VLOOKUP($D14,'Lista calciatori'!$B$2:$AW$549,6,FALSE),"") | G14: =IFERROR(VLOOKUP($D14,'Lista calciatori'!$B$2:$AW$549,14,FALSE),"") | H14: =IFERROR(VLOOKUP($D14,'Lista calciatori'!$B$2:$AW$549,30,FALSE),"") | J14: =IF(OR(H14="",I14=""),"",H14-I14) | K14: =IFERROR(VLOOKUP($D14,'Lista calciatori'!$B$2:$AW$549,42,FALSE),"")
A15: 5 | B15: Ds 2 — TITOLARE | C15: 4 | E15: =IFERROR(VLOOKUP($D15,'Lista calciatori'!$B$2:$AW$549,3,FALSE),"") | F15: =IFERROR(VLOOKUP($D15,'Lista calciatori'!$B$2:$AW$549,6,FALSE),"") | G15: =IFERROR(VLOOKUP($D15,'Lista calciatori'!$B$2:$AW$549,14,FALSE),"") | H15: =IFERROR(VLOOKUP($D15,'Lista calciatori'!$B$2:$AW$549,30,FALSE),"") | J15: =IF(OR(H15="",I15=""),"",H15-I15) | K15: =IFERROR(VLOOKUP($D15,'Lista calciatori'!$B$2:$AW$549,42,FALSE),"")
A16: 6 | B16: Ds 3 — SCOMMESSA | C16: 2 | E16: =IFERROR(VLOOKUP($D16,'Lista calciatori'!$B$2:$AW$549,3,FALSE),"") | F16: =IFERROR(VLOOKUP($D16,'Lista calciatori'!$B$2:$AW$549,6,FALSE),"") | G16: =IFERROR(VLOOKUP($D16,'Lista calciatori'!$B$2:$AW$549,14,FALSE),"") | H16: =IFERROR(VLOOKUP($D16,'Lista calciatori'!$B$2:$AW$549,30,FALSE),"") | J16: =IF(OR(H16="",I16=""),"",H16-I16) | K16: =IFERROR(VLOOKUP($D16,'Lista calciatori'!$B$2:$AW$549,42,FALSE),"")
A17: 7 | B17: Dc 1 — TOP | C17: 20 | E17: =IFERROR(VLOOKUP($D17,'Lista calciatori'!$B$2:$AW$549,3,FALSE),"") | F17: =IFERROR(VLOOKUP($D17,'Lista calciatori'!$B$2:$AW$549,6,FALSE),"") | G17: =IFERROR(VLOOKUP($D17,'Lista calciatori'!$B$2:$AW$549,14,FALSE),"") | H17: =IFERROR(VLOOKUP($D17,'Lista calciatori'!$B$2:$AW$549,30,FALSE),"") | J17: =IF(OR(H17="",I17=""),"",H17-I17) | K17: =IFERROR(VLOOKUP($D17,'Lista calciatori'!$B$2:$AW$549,42,FALSE),"")
A18: 8 | B18: Dc 2 — SEMITOP | C18: 4 | E18: =IFERROR(VLOOKUP($D18,'Lista calciatori'!$B$2:$AW$549,3,FALSE),"") | F18: =IFERROR(VLOOKUP($D18,'Lista calciatori'!$B$2:$AW$549,6,FALSE),"") | G18: =IFERROR(VLOOKUP($D18,'Lista calciatori'!$B$2:$AW$549,14,FALSE),"") | H18: =IFERROR(VLOOKUP($D18,'Lista calciatori'!$B$2:$AW$549,30,FALSE),"") | J18: =IF(OR(H18="",I18=""),"",H18-I18) | K18: =IFERROR(VLOOKUP($D18,'Lista calciatori'!$B$2:$AW$549,42,FALSE),"")
A19: 9 | B19: Dc 3 — TITOLARE | C19: 2 | E19: =IFERROR(VLOOKUP($D19,'Lista calciatori'!$B$2:$AW$549,3,FALSE),"") | F19: =IFERROR(VLOOKUP($D19,'Lista calciatori'!$B$2:$AW$549,6,FALSE),"") | G19: =IFERROR(VLOOKUP($D19,'Lista calciatori'!$B$2:$AW$549,14,FALSE),"") | H19: =IFERROR(VLOOKUP($D19,'Lista calciatori'!$B$2:$AW$549,30,FALSE),"") | J19: =IF(OR(H19="",I19=""),"",H19-I19) | K19: =IFERROR(VLOOKUP($D19,'Lista calciatori'!$B$2:$AW$549,42,FALSE),"")
A20: 10 | B20: Dc 4 — TITOLARE | C20: 2 | E20: =IFERROR(VLOOKUP($D20,'Lista calciatori'!$B$2:$AW$549,3,FALSE),"") | F20: =IFERROR(VLOOKUP($D20,'Lista calciatori'!$B$2:$AW$549,6,FALSE),"") | G20: =IFERROR(VLOOKUP($D20,'Lista calciatori'!$B$2:$AW$549,14,FALSE),"") | H20: =IFERROR(VLOOKUP($D20,'Lista calciatori'!$B$2:$AW$549,30,FALSE),"") | J20: =IF(OR(H20="",I20=""),"",H20-I20) | K20: =IFERROR(VLOOKUP($D20,'Lista calciatori'!$B$2:$AW$549,42,FALSE),"")
A21: 11 | B21: Dc 5 — LOW | C21: 2 | E21: =IFERROR(VLOOKUP($D21,'Lista calciatori'!$B$2:$AW$549,3,FALSE),"") | F21: =IFERROR(VLOOKUP($D21,'Lista calciatori'!$B$2:$AW$549,6,FALSE),"") | G21: =IFERROR(VLOOKUP($D21,'Lista calciatori'!$B$2:$AW$549,14,FALSE),"") | H21: =IFERROR(VLOOKUP($D21,'Lista calciatori'!$B$2:$AW$549,30,FALSE),"") | J21: =IF(OR(H21="",I21=""),"",H21-I21) | K21: =IFERROR(VLOOKUP($D21,'Lista calciatori'!$B$2:$AW$549,42,FALSE),"")
A22: 12 | B22: Jolly 1 — TITOLARE | C22: 4 | E22: =IFERROR(VLOOKUP($D22,'Lista calciatori'!$B$2:$AW$549,3,FALSE),"") | F22: =IFERROR(VLOOKUP($D22,'Lista calciatori'!$B$2:$AW$549,6,FALSE),"") | G22: =IFERROR(VLOOKUP($D22,'Lista calciatori'!$B$2:$AW$549,14,FALSE),"") | H22: =IFERROR(VLOOKUP($D22,'Lista calciatori'!$B$2:$AW$549,30,FALSE),"") | J22: =IF(OR(H22="",I22=""),"",H22-I22) | K22: =IFERROR(VLOOKUP($D22,'Lista calciatori'!$B$2:$AW$549,42,FALSE),"")
... A35: 25 | B35: Pc 2 — SEMITOP | C35: 27 | E35: =IFERROR(VLOOKUP($D35,'Lista calciatori'!$B$2:$AW$549,3,FALSE),"") | F35: =IFERROR(VLOOKUP($D35,'Lista calciatori'!$B$2:$AW$549,6,FALSE),"") | G35: =IFERROR(VLOOKUP($D35,'Lista calciatori'!$B$2:$AW$549,14,FALSE),"") | H35: =IFERROR(VLOOKUP($D35,'Lista calciatori'!$B$2:$AW$549,30,FALSE),"") | J35: =IF(OR(H35="",I35=""),"",H35-I35) | K35: =IFERROR(VLOOKUP($D35,'Lista calciatori'!$B$2:$AW$549,42,FALSE),"")
A38: PORTIERI — PUOI USARE PACCHETTO DI SQUADRA O 3 SINGOLI
A39: # | B39: Profilo | C39: Target | D39: Nome | E39: Squadra | F39: R. Mantra | G39: Tit.% | H39: Offerta max | I39: Costo pagato | J39: Scost. max | K39: Strategia | L39: Note live
A40: 1 | B40: Por | C40: 50 | E40: =IFERROR(VLOOKUP($D40,'Lista calciatori'!$B$2:$AW$549,3,FALSE),"") | F40: =IFERROR(VLOOKUP($D40,'Lista calciatori'!$B$2:$AW$549,6,FALSE),"") | G40: =IFERROR(VLOOKUP($D40,'Lista calciatori'!$B$2:$AW$549,14,FALSE),"") | H40: =IFERROR(VLOOKUP($D40,'Lista calciatori'!$B$2:$AW$549,30,FALSE),"") | J40: =IF(OR(H40="",I40=""),"",H40-I40) | K40: =IFERROR(VLOOKUP($D40,'Lista calciatori'!$B$2:$AW$549,42,FALSE),"")
A41: 2 | B41: Por | C41: 1 | E41: =IFERROR(VLOOKUP($D41,'Lista calciatori'!$B$2:$AW$549,3,FALSE),"") | F41: =IFERROR(VLOOKUP($D41,'Lista calciatori'!$B$2:$AW$549,6,FALSE),"") | G41: =IFERROR(VLOOKUP($D41,'Lista calciatori'!$B$2:$AW$549,14,FALSE),"") | H41: =IFERROR(VLOOKUP($D41,'Lista calciatori'!$B$2:$AW$549,30,FALSE),"") | J41: =IF(OR(H41="",I41=""),"",H41-I41) | K41: =IFERROR(VLOOKUP($D41,'Lista calciatori'!$B$2:$AW$549,42,FALSE),"")
A42: 3 | B42: Por | C42: 1 | E42: =IFERROR(VLOOKUP($D42,'Lista calciatori'!$B$2:$AW$549,3,FALSE),"") | F42: =IFERROR(VLOOKUP($D42,'Lista calciatori'!$B$2:$AW$549,6,FALSE),"") | G42: =IFERROR(VLOOKUP($D42,'Lista calciatori'!$B$2:$AW$549,14,FALSE),"") | H42: =IFERROR(VLOOKUP($D42,'Lista calciatori'!$B$2:$AW$549,30,FALSE),"") | J42: =IF(OR(H42="",I42=""),"",H42-I42) | K42: =IFERROR(VLOOKUP($D42,'Lista calciatori'!$B$2:$AW$549,42,FALSE),"")

Sheet Strategia 433
A1: STRATEGIA ASTA MANTRA 4-3-3 — 12 SQUADRE, 500 CREDITI — BOMBER + GIOIELLI
A2: Rimodulazione su prezzi reali della lega: cap più alti sui top, ma target di rosa aggressivo su Pc/A e recupero crediti con low cost, scommesse e coppie.
A4: PARAMETRI ASTA
A5: Budget totale | B5: 500 | C5: crediti
A6: Partecipanti | B6: 12 | C6: squadre
A7: Movimento | B7: 25 | C7: giocatori
A8: Portieri | B8: 3 | C8: giocatori
A9: Slot complessivi | B9: =B7+B8
A10: Somma QUOT top 336 | B10: 3152 | C10: Top 336 = 12 rose x 28 giocatori; calcolato dal listone nel file.
A11: Fattore inflazione 12x500 | B11: =B5*B6/B10 | C11: Benchmark aritmetico generico. I prezzi operativi ora sono tarati sullo storico della tua lega per ruolo.
A13: WALK-AWAY CAP PER FAMIGLIA E FASCIA — NON SONO I BUDGET TARGET
A14: Famiglia | B14: Budget reparto | C14: N. slot | D14: Top | E14: Semitop | F14: Starter | G14: Scommessa | H14: Low
A15: Por | B15: 52 | C15: 3 | D15: 60 | E15: 45 | F15: 30 | G15: 15 | H15: 6
A16: Dd | B16: 24 | C16: 3 | D16: 40 | E16: 28 | F16: 15 | G16: 8 | H16: 4
A17: Ds | B17: 24 | C17: 3 | D17: 40 | E17: 28 | F17: 15 | G17: 8 | H17: 4
A18: Dc | B18: 30 | C18: 5 | D18: 23 | E18: 15 | F18: 8 | G18: 5 | H18: 3
A19: Jolly | B19: 8 | C19: 2 | D19: 45 | E19: 30 | F19: 18 | G19: 10 | H19: 5
A20: A | B20: 100 | C20: 4 | D20: 85 | E20: 60 | F20: 40 | G20: 22 | H20: 10
A21: C | B21: 48 | C21: 3 | D21: 50 | E21: 35 | F21: 24 | G21: 14 | H21: 8
A22: M | B22: 42 | C22: 3 | D22: 38 | E22: 28 | F22: 20 | G22: 12 | H22: 7
A23: Pc | B23: 172 | C23: 2 | D23: 160 | E23: 110 | F23: 75 | G23: 40 | H23: 20
A24: Non433 | B24: 0 | C24: 0 | D24: 8 | E24: 6 | F24: 4 | G24: 3 | H24: 2
A25: TOTALE TARGET | B25: =SUM(B15:B23) | C25: =SUM(C15:C23)
A27: MOLTIPLICATORE EMPIRICO PREZZO / QUOT — STORICO LEGA 12x500 | E27: BUDGET SLOT — PIANO BOMBER + GIOIELLI (448 MOVIMENTO + 52 POR)
A28: Famiglia | B28: Moltiplicatore | C28: Logica | E28: Slot | F28: Profilo | G28: Target | H28: Regola
A29: Por | B29: 3 | C29: prime porte molto contese; pacchetto top 50-60 | E29: Dd 1 | F29: TOP | G29: 18 | H29: se va a 30-40, finanzialo tagliando altrove
A30: Dd | B30: 2.3 | C30: specialisti e ali di fascia possono salire molto | E30: Dd 2 | F30: TITOLARE | G30: 4 | H30: 90%+; cerca provincia
A31: Ds | B31: 2.3 | C31: specialisti e ali di fascia possono salire molto | E31: Dd 3 | F31: SCOMMESSA | G31: 2 | H31: gioiellino / copertura
A32: Dc | B32: 1.45 | C32: top circa 20-23, reparto profondo | E32: Ds 1 | F32: TOP | G32: 18 | H32: se va a 30-40, finanzialo tagliando altrove
A33: Jolly | B33: 1.55 | C33: premio alla versatilita ma senza all-in | E33: Ds 2 | F33: TITOLARE | G33: 4 | H33: 90%+; cerca provincia
A34: A | B34: 2.7 | C34: top spesso oltre 60 | E34: Ds 3 | F34: SCOMMESSA | G34: 2 | H34: gioiellino / copertura
A35: C | B35: 1.7 | C35: premio ai C offensivi/bonus | E35: Dc 1 | F35: TOP | G35: 20 | H35: cap reale 23
A36: M | B36: 1.3 | C36: titolari affidabili, inflazione più contenuta | E36: Dc 2 | F36: SEMITOP | G36: 4 | H36: reparto profondo: aspetta
A37: Pc | B37: 4.7 | C37: bomber fortemente inflazionati 130-150+ | E37: Dc 3 | F37: TITOLARE | G37: 2 | H37: minuti prima del nome
A38: Non433 | B38: 0.9 | C38: non prioritario nel 4-3-3 | E38: Dc 4 | F38: TITOLARE | G38: 2 | H38: minuti prima del nome
E39: Dc 5 | F39: LOW | G39: 2 | H39: scommessa / coppia
E40: Jolly 1 | F40: TITOLARE | G40: 4 | H40: versatile e titolare
E41: Jolly 2 | F41: TITOLARE | G41: 4 | H41: versatile e titolare
E42: A 1 | F42: TOP | G42: 65 | H42: strutturale per il 4-3-3; cap 85
E43: A 2 | F43: SEMITOP | G43: 22 | H43: qui cerca il vero affare
...

Sheet Graduatorie 433
A1: GRADUATORIE 4-3-3 — 30 NOMI PER RUOLO + GIOIELLI E COPERTURE
A2: Graduatoria ampia: core + titolari value + promesse di seconda/terza fascia. “Prezzo obiettivo” è il prezzo desiderato; “Offerta max” è il walk-away cap.
A3: Fotografia 28/08/2026: mercato ancora aperto. Le coppie sono coperture tattiche/di ruolo da ricontrollare al 02/09, non garanzia di gerarchia.
A5: Ruolo | B5: Rank | C5: Nome | D5: Squadra | E5: R. Mantra | F5: Profilo asta | G5: Tier SOS | H5: Tit.% | I5: Indice Fanta | J5: QUOT | K5: FVM 500 | L5: Prezzo obiettivo | M5: Offerta max | N5: Delta | O5: Coppia/copertura | P5: Strategia | Q5: Rischio | R5: Perché | S5: Fonte
A6: Dd | B6: 1 | C6: Di Lorenzo | D6: Napoli | E6: Dd/E | F6: TOP | G6: TOP | H6: 98 | I6: =IFERROR(VLOOKUP(C6,'Lista calciatori'!$B$2:$AX$549,16,FALSE),"") | J6: 12 | K6: 20 | L6: =IFERROR(VLOOKUP(C6,'Lista calciatori'!$B$2:$AX$549,49,FALSE),"") | M6: =IFERROR(VLOOKUP(C6,'Lista calciatori'!$B$2:$AX$549,30,FALSE),"") | N6: =M6-L6 | O6: Favasuli | P6: =IFERROR(VLOOKUP(C6,'Lista calciatori'!$B$2:$AX$549,42,FALSE),"") | Q6: BASSO | R6: esterno utile al 4-3-3; pagalo premium solo se non compri due top di fascia | S6: https://www.sosfanta.com/guida-asta-fantacalcio/fantacalcio-mantra-ecco-la-guida-allasta-2026-27-la-divisione-ruolo-per-ruolo/
A7: Dd | B7: 2 | C7: Jimenez A. | D7: Fiorentina | E7: Dd/Ds/E | F7: TOP | G7: TOP | H7: 75 | I7: =IFERROR(VLOOKUP(C7,'Lista calciatori'!$B$2:$AX$549,16,FALSE),"") | J7: 9 | K7: 13 | L7: =IFERROR(VLOOKUP(C7,'Lista calciatori'!$B$2:$AX$549,49,FALSE),"") | M7: =IFERROR(VLOOKUP(C7,'Lista calciatori'!$B$2:$AX$549,30,FALSE),"") | N7: =M7-L7 | O7: Joao Mario | P7: =IFERROR(VLOOKUP(C7,'Lista calciatori'!$B$2:$AX$549,42,FALSE),"") | Q7: BALLOTTAGGIO | R7: esterno utile al 4-3-3; pagalo premium solo se non compri due top di fascia | S7: https://www.sosfanta.com/guida-asta-fantacalcio/fantacalcio-mantra-ecco-la-guida-allasta-2026-27-la-divisione-ruolo-per-ruolo/
A8: Dd | B8: 3 | C8: Dodò | D8: Fiorentina | E8: Dd/E | F8: TOP | G8: TOP | H8: 51 | I8: =IFERROR(VLOOKUP(C8,'Lista calciatori'!$B$2:$AX$549,16,FALSE),"") | J8: 10 | K8: 10 | L8: =IFERROR(VLOOKUP(C8,'Lista calciatori'!$B$2:$AX$549,49,FALSE),"") | M8: =IFERROR(VLOOKUP(C8,'Lista calciatori'!$B$2:$AX$549,30,FALSE),"") | N8: =M8-L8 | O8: Joao Mario | P8: =IFERROR(VLOOKUP(C8,'Lista calciatori'!$B$2:$AX$549,42,FALSE),"") | Q8: BALLOTTAGGIO | R8: esterno utile al 4-3-3; pagalo premium solo se non compri due top di fascia | S8: https://www.sosfanta.com/guida-asta-fantacalcio/fantacalcio-mantra-ecco-la-guida-allasta-2026-27-la-divisione-ruolo-per-ruolo/
A9: Dd | B9: 4 | C9: Kalulu | D9: Juventus | E9: Dd/Dc | F9: SEMITOP | G9: SEMITOP | H9: 98 | I9: =IFERROR(VLOOKUP(C9,'Lista calciatori'!$B$2:$AX$549,16,FALSE),"") | J9: 14 | K9: 24 | L9: =IFERROR(VLOOKUP(C9,'Lista calciatori'!$B$2:$AX$549,49,FALSE),"") | M9: =IFERROR(VLOOKUP(C9,'Lista calciatori'!$B$2:$AX$549,30,FALSE),"") | N9: =M9-L9 | O9: Gatti | P9: =IFERROR(VLOOKUP(C9,'Lista calciatori'!$B$2:$AX$549,42,FALSE),"") | Q9: BASSO | R9: esterno utile al 4-3-3; pagalo premium solo se non compri due top di fascia | S9: https://www.sosfanta.com/guida-asta-fantacalcio/fantacalcio-mantra-ecco-la-guida-allasta-2026-27-la-divisione-ruolo-per-ruolo/
A10: Dd | B10: 5 | C10: Cambiaso | D10: Juventus | E10: Dd/Ds/E | F10: SEMITOP | G10: SEMITOP | H10: 98 | I10: =IFERROR(VLOOKUP(C10,'Lista calciatori'!$B$2:$AX$549,16,FALSE),"") | J10: 10 | K10: 14 | L10: =IFERROR(VLOOKUP(C10,'Lista calciatori'!$B$2:$AX$549,49,FALSE),"") | M10: =IFERROR(VLOOKUP(C10,'Lista calciatori'!$B$2:$AX$549,30,FALSE),"") | N10: =M10-L10 | O10: Celik | P10: =IFERROR(VLOOKUP(C10,'Lista calciatori'!$B$2:$AX$549,42,FALSE),"") | Q10: BASSO | R10: esterno utile al 4-3-3; pagalo premium solo se non compri due top di fascia | S10: https://www.sosfanta.com/guida-asta-fantacalcio/fantacalcio-mantra-ecco-la-guida-allasta-2026-27-la-divisione-ruolo-per-ruolo/
A11: Dd | B11: 6 | C11: Zappacosta | D11: Atalanta | E11: Dd/E | F11: SEMITOP | G11: SEMITOP | H11: 82 | I11: =IFERROR(VLOOKUP(C11,'Lista calciatori'!$B$2:$AX$549,16,FALSE),"") | J11: 8 | K11: 10 | L11: =IFERROR(VLOOKUP(C11,'Lista calciatori'!$B$2:$AX$549,49,FALSE),"") | M11: =IFERROR(VLOOKUP(C11,'Lista calciatori'!$B$2:$AX$549,30,FALSE),"") | N11: =M11-L11 | O11: Bellanova | P11: =IFERROR(VLOOKUP(C11,'Lista calciatori'!$B$2:$AX$549,42,FALSE),"") | Q11: BALLOTTAGGIO | R11: esterno utile al 4-3-3; pagalo premium solo se non compri due top di fascia | S11: https://www.sosfanta.com/guida-asta-fantacalcio/fantacalcio-mantra-ecco-la-guida-allasta-2026-27-la-divisione-ruolo-per-ruolo/
A12: Dd | B12: 7 | C12: Delprato | D12: Parma | E12: B/Dd/E | F12: TITOLARE VALUE | G12: SOTTO AI SEMITOP | H12: 98 | I12: =IFERROR(VLOOKUP(C12,'Lista calciatori'!$B$2:$AX$549,16,FALSE),"") | J12: 8 | K12: 12 | L12: =IFERROR(VLOOKUP(C12,'Lista calciatori'!$B$2:$AX$549,49,FALSE),"") | M12: =IFERROR(VLOOKUP(C12,'Lista calciatori'!$B$2:$AX$549,30,FALSE),"") | N12: =M12-L12 | O12: Britschgi | P12: =IFERROR(VLOOKUP(C12,'Lista calciatori'!$B$2:$AX$549,42,FALSE),"") | Q12: BASSO | R12: esterno utile al 4-3-3; pagalo premium solo se non compri due top di fascia | S12: https://www.sosfanta.com/guida-asta-fantacalcio/fantacalcio-mantra-ecco-la-guida-allasta-2026-27-la-divisione-ruolo-per-ruolo/
A13: Dd | B13: 8 | C13: Chalobah T. | D13: Como | E13: Dd/Dc | F13: JOLLY / COPERTURA | G13: SOTTO AI SEMITOP | H13: 82 | I13: =IFERROR(VLOOKUP(C13,'Lista calciatori'!$B$2:$AX$549,16,FALSE),"") | J13: 10 | K13: 16 | L13: =IFERROR(VLOOKUP(C13,'Lista calciatori'!$B$2:$AX$549,49,FALSE),"") | M13: =IFERROR(VLOOKUP(C13,'Lista calciatori'!$B$2:$AX$549,30,FALSE),"") | N13: =M13-L13 | O13: Kambwala | P13: =IFERROR(VLOOKUP(C13,'Lista calciatori'!$B$2:$AX$549,42,FALSE),"") | Q13: BALLOTTAGGIO | R13: esterno utile al 4-3-3; pagalo premium solo se non compri due top di fascia | S13: https://www.sosfanta.com/guida-asta-fantacalcio/fantacalcio-mantra-ecco-la-guida-allasta-2026-27-la-divisione-ruolo-per-ruolo/
A14: Dd | B14: 9 | C14: Vojvoda | D14: Udinese | E14: Dd/E | F14: TITOLARE VALUE | G14: SOTTO AI SEMITOP | H14: 98 | I14: =IFERROR(VLOOKUP(C14,'Lista calciatori'!$B$2:$AX$549,16,FALSE),"") | J14: 8 | K14: 10 | L14: =IFERROR(VLOOKUP(C14,'Lista calciatori'!$B$2:$AX$549,49,FALSE),"") | M14: =IFERROR(VLOOKUP(C14,'Lista calciatori'!$B$2:$AX$549,30,FALSE),"") | N14: =M14-L14 | O14: Zanoli | P14: =IFERROR(VLOOKUP(C14,'Lista calciatori'!$B$2:$AX$549,42,FALSE),"") | Q14: BASSO | R14: valore aumentato dalla possibile copertura di squadra/ruolo | S14: https://www.sosfanta.com/guida-asta-fantacalcio/fantacalcio-mantra-ecco-la-guida-allasta-2026-27-la-divisione-ruolo-per-ruolo/
A15: Dd | B15: 10 | C15: Zortea | D15: Bologna | E15: Dd/E | F15: TITOLARE VALUE | G15: SOTTO AI SEMITOP | H15: 98 | I15: =IFERROR(VLOOKUP(C15,'Lista calciatori'!$B$2:$AX$549,16,FALSE),"") | J15: 6 | K15: 10 | L15: =IFERROR(VLOOKUP(C15,'Lista calciatori'!$B$2:$AX$549,49,FALSE),"") | M15: =IFERROR(VLOOKUP(C15,'Lista calciatori'!$B$2:$AX$549,30,FALSE),"") | N15: =M15-L15 | O15: Holm | P15: =IFERROR(VLOOKUP(C15,'Lista calciatori'!$B$2:$AX$549,42,FALSE),"") | Q15: BASSO | R15: valore aumentato dalla possibile copertura di squadra/ruolo | S15: https://www.sosfanta.com/guida-asta-fantacalcio/fantacalcio-mantra-ecco-la-guida-allasta-2026-27-la-divisione-ruolo-per-ruolo/
A16: Dd | B16: 11 | C16: Celik | D16: Juventus | E16: B/Dd/E | F16: LOW COST | G16: SOTTO AI SEMITOP | H16: 51 | I16: =IFERROR(VLOOKUP(C16,'Lista calciatori'!$B$2:$AX$549,16,FALSE),"") | J16: 9 | K16: 9 | L16: =IFERROR(VLOOKUP(C16,'Lista calciatori'!$B$2:$AX$549,49,FALSE),"") | M16: =IFERROR(VLOOKUP(C16,'Lista calciatori'!$B$2:$AX$549,30,FALSE),"") | N16: =M16-L16 | O16: Cabal | P16: =IFERROR(VLOOKUP(C16,'Lista calciatori'!$B$2:$AX$549,42,FALSE),"") | Q16: BALLOTTAGGIO | R16: minuti a prezzo basso: utile per finanziare Pc/A | S16: https://www.sosfanta.com/guida-asta-fantacalcio/fantacalcio-mantra-ecco-la-guida-allasta-2026-27-la-divisione-ruolo-per-ruolo/
A17: Dd | B17: 12 | C17: Couto | D17: Como | E17: Dd/E | F17: GIOIELLINO | G17: POSSIBILI SORPRESE | H17: 82 | I17: =IFERROR(VLOOKUP(C17,'Lista calciatori'!$B$2:$AX$549,16,FALSE),"") | J17: 8 | K17: 13 | L17: =IFERROR(VLOOKUP(C17,'Lista calciatori'!$B$2:$AX$549,49,FALSE),"") | M17: =IFERROR(VLOOKUP(C17,'Lista calciatori'!$B$2:$AX$549,30,FALSE),"") | N17: =M17-L17 | O17: Smolcic I. | P17: =IFERROR(VLOOKUP(C17,'Lista calciatori'!$B$2:$AX$549,42,FALSE),"") | Q17: BALLOTTAGGIO | R17: upside + costo contenuto; profilo da battere presto o a fine reparto | S17: https://www.sosfanta.com/guida-asta-fantacalcio/fantacalcio-mantra-ecco-la-guida-allasta-2026-27-la-divisione-ruolo-per-ruolo/
... A20: Dd | B20: 15 | C20: Bellanova | D20: Atalanta | E20: Dd/E | F20: JOLLY / COPERTURA | G20: JOLLY 1ª FASCIA | H20: 47 | I20: =IFERROR(VLOOKUP(C20,'Lista calciatori'!$B$2:$AX$549,16,FALSE),"") | J20: 6 | K20: 9 | L20: =IFERROR(VLOOKUP(C20,'Lista calciatori'!$B$2:$AX$549,49,FALSE),"") | M20: =IFERROR(VLOOKUP(C20,'Lista calciatori'!$B$2:$AX$549,30,FALSE),"") | N20: =M20-L20 | O20: Kossounou | P20: =IFERROR(VLOOKUP(C20,'Lista calciatori'!$B$2:$AX$549,42,FALSE),"") | Q20: BALLOTTAGGIO | R20: valore aumentato dalla possibile copertura di squadra/ruolo | S20: https://www.sosfanta.com/guida-asta-fantacalcio/fantacalcio-mantra-ecco-la-guida-allasta-2026-27-la-divisione-ruolo-per-ruolo/
A21: Dd | B21: 16 | C21: Pavard | D21: Inter | E21: Dd/Dc | F21: JOLLY / COPERTURA | G21: JOLLY 1ª FASCIA | H21: 40 | I21: =IFERROR(VLOOKUP(C21,'Lista calciatori'!$B$2:$AX$549,16,FALSE),"") | J21: 7 | K21: 8 | L21: =IFERROR(VLOOKUP(C21,'Lista calciatori'!$B$2:$AX$549,49,FALSE),"") | M21: =IFERROR(VLOOKUP(C21,'Lista calciatori'!$B$2:$AX$549,30,FALSE),"") | N21: =M21-L21 | P21: =IFERROR(VLOOKUP(C21,'Lista calciatori'!$B$2:$AX$549,42,FALSE),"") | Q21: MEDIO | R21: alternativa credibile per allargare il ventaglio d asta | S21: https://www.sosfanta.com/guida-asta-fantacalcio/fantacalcio-mantra-ecco-la-guida-allasta-2026-27-la-divisione-ruolo-per-ruolo/
A22: Dd | B22: 17 | C22: Zanoli | D22: Udinese | E22: Dd/E | F22: LOW COST | G22: JOLLY 1ª FASCIA | H22: 30 | I22: =IFERROR(VLOOKUP(C22,'Lista calciatori'!$B$2:$AX$549,16,FALSE),"") | J22: 4 | K22: 5 | L22: =IFERROR(VLOOKUP(C22,'Lista calciatori'!$B$2:$AX$549,49,FALSE),"") | M22: =IFERROR(VLOOKUP(C22,'Lista calciatori'!$B$2:$AX$549,30,FALSE),"") | N22: =M22-L22 | P22: =IFERROR(VLOOKUP(C22,'Lista calciatori'!$B$2:$AX$549,42,FALSE),"") | Q22: MEDIO | R22: minuti a prezzo basso: utile per finanziare Pc/A | S22: https://www.sosfanta.com/guida-asta-fantacalcio/fantacalcio-mantra-ecco-la-guida-allasta-2026-27-la-divisione-ruolo-per-ruolo/
A23: Dd | B23: 18 | C23: Rensch | D23: Roma | E23: B/Dd/E | F23: TITOLARE VALUE | G23: JOLLY 2ª FASCIA | H23: 87 | I23: =IFERROR(VLOOKUP(C23,'Lista calciatori'!$B$2:$AX$549,16,FALSE),"") | J23: 6 | K23: 8 | L23: =IFERROR(VLOOKUP(C23,'Lista calciatori'!$B$2:$AX$549,49,FALSE),"") | M23: =IFERROR(VLOOKUP(C23,'Lista calciatori'!$B$2:$AX$549,30,FALSE),"") | N23: =M23-L23 | O23: Lulli | P23: =IFERROR(VLOOKUP(C23,'Lista calciatori'!$B$2:$AX$549,42,FALSE),"") | Q23: INFORTUNIO — da monitorare | R23: valore aumentato dalla possibile copertura di squadra/ruolo | S23: https://www.sosfanta.com/guida-asta-fantacalcio/fantacalcio-mantra-ecco-la-guida-allasta-2026-27-la-divisione-ruolo-per-ruolo/
A24: Dd | B24: 19 | C24: Joao Mario | D24: Fiorentina | E24: Dd/E | F24: LOW COST | G24: JOLLY 2ª FASCIA | H24: 58 | I24: =IFERROR(VLOOKUP(C24,'Lista calciatori'!$B$2:$AX$549,16,FALSE),"") | J24: 3 | K24: 6 | L24: =IFERROR(VLOOKUP(C24,'Lista calciatori'!$B$2:$AX$549,49,FALSE),"") | M24: =IFERROR(VLOOKUP(C24,'Lista calciatori'!$B$2:$AX$549,30,FALSE),"") | N24: =M24-L24 | O24: Dodò | P24: =IFERROR(VLOOKUP(C24,'Lista calciatori'!$B$2:$AX$549,42,FALSE),"") | Q24: BALLOTTAGGIO | R24: minuti a prezzo basso: utile per finanziare Pc/A | S24: https://www.sosfanta.com/guida-asta-fantacalcio/fantacalcio-mantra-ecco-la-guida-allasta-2026-27-la-divisione-ruolo-per-ruolo/
A25: Dd | B25: 20 | C25: Holm | D25: Bologna | E25: Dd/E | F25: LOW COST | G25: JOLLY 2ª FASCIA | H25: 42 | I25: =IFERROR(VLOOKUP(C25,'Lista calciatori'!$B$2:$AX$549,16,FALSE),"") | J25: 5 | K25: 7 | L25: =IFERROR(VLOOKUP(C25,'Lista calciatori'!$B$2:$AX$549,49,FALSE),"") | M25: =IFERROR(VLOOKUP(C25,'Lista calciatori'!$B$2:$AX$549,30,FALSE),"") | N25: =M25-L25 | O25: De Silvestri | P25: =IFERROR(VLOOKUP(C25,'Lista calciatori'!$B$2:$AX$549,42,FALSE),"") | Q25: MEDIO | R25: minuti a prezzo basso: utile per finanziare Pc/A | S25: https://www.sosfanta.com/guida-asta-fantacalcio/fantacalcio-mantra-ecco-la-guida-allasta-2026-27-la-divisione-ruolo-per-ruolo/
A26: Dd | B26: 21 | C26: Norton-Cuffy | D26: Genoa | E26: Dd/E | F26: TITOLARE VALUE | G26: LOW COST 1ª FASCIA | H26: 98 | I26: =IFERROR(VLOOKUP(C26,'Lista calciatori'!$B$2:$AX$549,16,FALSE),"") | J26: 8 | K26: 11 | L26: =IFERROR(VLOOKUP(C26,'Lista calciatori'!$B$2:$AX$549,49,FALSE),"") | M26: =IFERROR(VLOOKUP(C26,'Lista calciatori'!$B$2:$AX$549,30,FALSE),"") | N26: =M26-L26 | O26: Sabelli | P26: =IFERROR(VLOOKUP(C26,'Lista calciatori'!$B$2:$AX$549,42,FALSE),"") | Q26: BASSO | R26: valore aumentato dalla possibile copertura di squadra/ruolo | S26: https://www.sosfanta.com/guida-asta-fantacalcio/fantacalcio-mantra-ecco-la-guida-allasta-2026-27-la-divisione-ruolo-per-ruolo/
A27: Dd | B27: 22 | C27: Marusic | D27: Lazio | E27: Dd/Ds/E | F27: LOW COST | G27: LOW COST 1ª FASCIA | H27: 60 | I27: =IFERROR(VLOOKUP(C27,'Lista calciatori'!$B$2:$AX$549,16,FALSE),"") | J27: 6 | K27: 12 | L27: =IFERROR(VLOOKUP(C27,'Lista calciatori'!$B$2:$AX$549,49,FALSE),"") | M27: =IFERROR(VLOOKUP(C27,'Lista calciatori'!$B$2:$AX$549,30,FALSE),"") | N27: =M27-L27 | O27: Pedraza | P27: =IFERROR(VLOOKUP(C27,'Lista calciatori'!$B$2:$AX$549,42,FALSE),"") | Q27: INFORTUNIO | R27: minuti a prezzo basso: utile per finanziare Pc/A | S27: https://www.sosfanta.com/guida-asta-fantacalcio/fantacalcio-mantra-ecco-la-guida-allasta-2026-27-la-divisione-ruolo-per-ruolo/
A28: Dd | B28: 23 | C28: Birindelli | D28: Monza | E28: Dd/Ds/E | F28: JOLLY / COPERTURA | G28: LOW COST 1ª FASCIA | H28: 82 | I28: =IFERROR(VLOOKUP(C28,'Lista calciatori'!$B$2:$AX$549,16,FALSE),"") | J28: 5 | K28: 7 | L28: =IFERROR(VLOOKUP(C28,'Lista calciatori'!$B$2:$AX$549,49,FALSE),"") | M28: =IFERROR(VLOOKUP(C28,'Lista calciatori'!$B$2:$AX$549,30,FALSE),"") | N28: =M28-L28 | O28: Carboni A. | P28: =IFERROR(VLOOKUP(C28,'Lista calciatori'!$B$2:$AX$549,42,FALSE),"") | Q28: BALLOTTAGGIO | R28: valore aumentato dalla possibile copertura di squadra/ruolo | S28: https://www.sosfanta.com/guida-asta-fantacalcio/fantacalcio-mantra-ecco-la-guida-allasta-2026-27-la-divisione-ruolo-per-ruolo/
A29: Dd | B29: 24 | C29: Pedersen | D29: Torino | E29: Dd/E | F29: TITOLARE VALUE | G29: LOW COST 1ª FASCIA | H29: 91 | I29: =IFERROR(VLOOKUP(C29,'Lista calciatori'!$B$2:$AX$549,16,FALSE),"") | J29: 5 | K29: 6 | L29: =IFERROR(VLOOKUP(C29,'Lista calciatori'!$B$2:$AX$549,49,FALSE),"") | M29: =IFERROR(VLOOKUP(C29,'Lista calciatori'!$B$2:$AX$549,30,FALSE),"") | N29: =M29-L29 | O29: Fortini | P29: =IFERROR(VLOOKUP(C29,'Lista calciatori'!$B$2:$AX$549,42,FALSE),"") | Q29: BASSO | R29: valore aumentato dalla possibile copertura di squadra/ruolo | S29: https://www.sosfanta.com/guida-asta-fantacalcio/fantacalcio-mantra-ecco-la-guida-allasta-2026-27-la-divisione-ruolo-per-ruolo/
A30: Dd | B30: 25 | C30: Veiga D. | D30: Lecce | E30: Dd/E | F30: TITOLARE VALUE | G30: LOW COST 2ª FASCIA | H30: 98 | I30: =IFERROR(VLOOKUP(C30,'Lista calciatori'!$B$2:$AX$549,16,FALSE),"") | J30: 6 | K30: 6 | L30: =IFERROR(VLOOKUP(C30,'Lista calciatori'!$B$2:$AX$549,49,FALSE),"") | M30: =IFERROR(VLOOKUP(C30,'Lista calciatori'!$B$2:$AX$549,30,FALSE),"") | N30: =M30-L30 | O30: Ndaba | P30: =IFERROR(VLOOKUP(C30,'Lista calciatori'!$B$2:$AX$549,42,FALSE),"") | Q30: BASSO | R30: valore aumentato dalla possibile copertura di squadra/ruolo | S30: https://www.sosfanta.com/guida-asta-fantacalcio/fantacalcio-mantra-ecco-la-guida-allasta-2026-27-la-divisione-ruolo-per-ruolo/
A31: Dd | B31: 26 | C31: Oyono A. | D31: Frosinone | E31: Dd/E | F31: TITOLARE VALUE | G31: LOW COST 2ª FASCIA | H31: 91 | I31: =IFERROR(VLOOKUP(C31,'Lista calciatori'!$B$2:$AX$549,16,FALSE),"") | J31: 5 | K31: 5 | L31: =IFERROR(VLOOKUP(C31,'Lista calciatori'!$B$2:$AX$549,49,FALSE),"") | M31: =IFERROR(VLOOKUP(C31,'Lista calciatori'!$B$2:$AX$549,30,FALSE),"") | N31: =M31-L31 | O31: Tchato | P31: =IFERROR(VLOOKUP(C31,'Lista calciatori'!$B$2:$AX$549,42,FALSE),"") | Q31: BASSO | R31: valore aumentato dalla possibile copertura di squadra/ruolo | S31: https://www.sosfanta.com/guida-asta-fantacalcio/fantacalcio-mantra-ecco-la-guida-allasta-2026-27-la-divisione-ruolo-per-ruolo/
A32: Dd | B32: 27 | C32: Walukiewicz | D32: Sassuolo | E32: Dd/Dc | F32: JOLLY / COPERTURA | G32: LOW COST 2ª FASCIA | H32: 71 | I32: =IFERROR(VLOOKUP(C32,'Lista calciatori'!$B$2:$AX$549,16,FALSE),"") | J32: 4 | K32: 6 | L32: =IFERROR(VLOOKUP(C32,'Lista calciatori'!$B$2:$AX$549,49,FALSE),"") | M32: =IFERROR(VLOOKUP(C32,'Lista calciatori'!$B$2:$AX$549,30,FALSE),"") | N32: =M32-L32 | O32: Cinquegrano | P32: =IFERROR(VLOOKUP(C32,'Lista calciatori'!$B$2:$AX$549,42,FALSE),"") | Q32: BALLOTTAGGIO | R32: valore aumentato dalla possibile copertura di squadra/ruolo | S32: https://www.sosfanta.com/guida-asta-fantacalcio/fantacalcio-mantra-ecco-la-guida-allasta-2026-27-la-divisione-ruolo-per-ruolo/
A33: Dd | B33: 28 | C33: Bertola | D33: Udinese | E33: Dd/Ds/Dc | F33: JOLLY / COPERTURA | G33: JOLLY 3ª FASCIA | H33: 78 | I33: =IFERROR(VLOOKUP(C33,'Lista calciatori'!$B$2:$AX$549,16,FALSE),"") | J33: 6 | K33: 7 | L33: =IFERROR(VLOOKUP(C33,'Lista calciatori'!$B$2:$AX$549,49,FALSE),"") | M33: =IFERROR(VLOOKUP(C33,'Lista calciatori'!$B$2:$AX$549,30,FALSE),"") | N33: =M33-L33 | O33: Ebosse | P33: =IFERROR(VLOOKUP(C33,'Lista calciatori'!$B$2:$AX$549,42,FALSE),"") | Q33: BALLOTTAGGIO | R33: valore aumentato dalla possibile copertura di squadra/ruolo | S33: https://www.sosfanta.com/guida-asta-fantacalcio/fantacalcio-mantra-ecco-la-guida-allasta-2026-27-la-divisione-ruolo-per-ruolo/
A34: Dd | B34: 29 | C34: Helland | D34: Bologna | E34: Dd/Dc | F34: LOW COST | G34: JOLLY 3ª FASCIA | H34: 82 | I34: =IFERROR(VLOOKUP(C34,'Lista calciatori'!$B$2:$AX$549,16,FALSE),"") | J34: 3 | K34: 6 | L34: =IFERROR(VLOOKUP(C34,'Lista calciatori'!$B$2:$AX$549,49,FALSE),"") | M34: =IFERROR(VLOOKUP(C34,'Lista calciatori'!$B$2:$AX$549,30,FALSE),"") | N34: =M34-L34 | O34: De Silvestri | P34: =IFERROR(VLOOKUP(C34,'Lista calciatori'!$B$2:$AX$549,42,FALSE),"") | Q34: BASSO | R34: minuti a prezzo basso: utile per finanziare Pc/A | S34: https://www.sosfanta.com/guida-asta-fantacalcio/fantacalcio-mantra-ecco-la-guida-allasta-2026-27-la-divisione-ruolo-per-ruolo/
... A52: Ds | B52: 16 | C52: Valdepenas | D52: Fiorentina | E52: Ds/Dc | F52: GIOIELLINO | G52: SCOMMESSE | H52: 78 | I52: =IFERROR(VLOOKUP(C52,'Lista calciatori'!$B$2:$AX$549,16,FALSE),"") | J52: 7 | K52: 10 | L52: =IFERROR(VLOOKUP(C52,'Lista calciatori'!$B$2:$AX$549,49,FALSE),"") | M52: =IFERROR(VLOOKUP(C52,'Lista calciatori'!$B$2:$AX$549,30,FALSE),"") | N52: =M52-L52 | O52: Ranieri L. | P52: =IFERROR(VLOOKUP(C52,'Lista calciatori'!$B$2:$AX$549,42,FALSE),"") | Q52: BALLOTTAGGIO | R52: upside + costo contenuto; profilo da battere presto o a fine reparto | S52: https://www.sosfanta.com/guida-asta-fantacalcio/fantacalcio-mantra-ecco-la-guida-allasta-2026-27-la-divisione-ruolo-per-ruolo/
A53: Ds | B53: 17 | C53: Ahanor | D53: Atalanta | E53: B/Ds/E | F53: GIOIELLINO | G53: SCOMMESSE | H53: 43 | I53: =IFERROR(VLOOKUP(C53,'Lista calciatori'!$B$2:$AX$549,16,FALSE),"") | J53: 7 | K53: 8 | L53: =IFERROR(VLOOKUP(C53,'Lista calciatori'!$B$2:$AX$549,49,FALSE),"") | M53: =IFERROR(VLOOKUP(C53,'Lista calciatori'!$B$2:$AX$549,30,FALSE),"") | N53: =M53-L53 | P53: =IFERROR(VLOOKUP(C53,'Lista calciatori'!$B$2:$AX$549,42,FALSE),"") | Q53: A RISCHIO + BALLOTTAGGIO | R53: upside + costo contenuto; profilo da battere presto o a fine reparto | S53: https://www.sosfanta.com/guida-asta-fantacalcio/fantacalcio-mantra-ecco-la-guida-allasta-2026-27-la-divisione-ruolo-per-ruolo/
A54: Ds | B54: 18 | C54: Mitaj | D54: Genoa | E54: Ds/E | F54: GIOIELLINO | G54: SCOMMESSE | H54: 30 | I54: =IFERROR(VLOOKUP(C54,'Lista calciatori'!$B$2:$AX$549,16,FALSE),"") | J54: 4 | K54: 5 | L54: =IFERROR(VLOOKUP(C54,'Lista calciatori'!$B$2:$AX$549,49,FALSE),"") | M54: =IFERROR(VLOOKUP(C54,'Lista calciatori'!$B$2:$AX$549,30,FALSE),"") | N54: =M54-L54 | O54: Sabelli | P54: =IFERROR(VLOOKUP(C54,'Lista calciatori'!$B$2:$AX$549,42,FALSE),"") | Q54: MEDIO | R54: upside + costo contenuto; profilo da battere presto o a fine reparto | S54: https://www.sosfanta.com/guida-asta-fantacalcio/fantacalcio-mantra-ecco-la-guida-allasta-2026-27-la-divisione-ruolo-per-ruolo/
A55: Ds | B55: 19 | C55: Heggem | D55: Bologna | E55: Ds/Dc | F55: JOLLY / COPERTURA | G55: JOLLY 2ª FASCIA | H55: 82 | I55: =IFERROR(VLOOKUP(C55,'Lista calciatori'!$B$2:$AX$549,16,FALSE),"") | J55: 7 | K55: 9 | L55: =IFERROR(VLOOKUP(C55,'Lista calciatori'!$B$2:$AX$549,49,FALSE),"") | M55: =IFERROR(VLOOKUP(C55,'Lista calciatori'!$B$2:$AX$549,30,FALSE),"") | N55: =M55-L55 | O55: Helland | P55: =IFERROR(VLOOKUP(C55,'Lista calciatori'!$B$2:$AX$549,42,FALSE),"") | Q55: BALLOTTAGGIO | R55: valore aumentato dalla possibile copertura di squadra/ruolo | S55: https://www.sosfanta.com/guida-asta-fantacalcio/fantacalcio-mantra-ecco-la-guida-allasta-2026-27-la-divisione-ruolo-per-ruolo/
A56: Ds | B56: 20 | C56: Kelly L. | D56: Juventus | E56: Ds/Dc | F56: JOLLY / COPERTURA | G56: JOLLY 2ª FASCIA | H56: 82 | I56: =IFERROR(VLOOKUP(C56,'Lista calciatori'!$B$2:$AX$549,16,FALSE),"") | J56: 6 | K56: 7 | L56: =IFERROR(VLOOKUP(C56,'Lista calciatori'!$B$2:$AX$549,49,FALSE),"") | M56: =IFERROR(VLOOKUP(C56,'Lista calciatori'!$B$2:$AX$549,30,FALSE),"") | N56: =M56-L56 | O56: Cabal | P56: =IFERROR(VLOOKUP(C56,'Lista calciatori'!$B$2:$AX$549,42,FALSE),"") | Q56: BALLOTTAGGIO | R56: valore aumentato dalla possibile copertura di squadra/ruolo | S56: https://www.sosfanta.com/guida-asta-fantacalcio/fantacalcio-mantra-ecco-la-guida-allasta-2026-27-la-divisione-ruolo-per-ruolo/
A57: Ds | B57: 21 | C57: Olivera | D57: Napoli | E57: B/Ds/E | F57: LOW COST | G57: JOLLY 2ª FASCIA | H57: 47 | I57: =IFERROR(VLOOKUP(C57,'Lista calciatori'!$B$2:$AX$549,16,FALSE),"") | J57: 6 | K57: 8 | L57: =IFERROR(VLOOKUP(C57,'Lista calciatori'!$B$2:$AX$549,49,FALSE),"") | M57: =IFERROR(VLOOKUP(C57,'Lista calciatori'!$B$2:$AX$549,30,FALSE),"") | N57: =M57-L57 | O57: Mazzocchi | P57: =IFERROR(VLOOKUP(C57,'Lista calciatori'!$B$2:$AX$549,42,FALSE),"") | Q57: BALLOTTAGGIO | R57: minuti a prezzo basso: utile per finanziare Pc/A | S57: https://www.sosfanta.com/guida-asta-fantacalcio/fantacalcio-mantra-ecco-la-guida-allasta-2026-27-la-divisione-ruolo-per-ruolo/
A58: Ds | B58: 22 | C58: Gallo | D58: Lecce | E58: Ds/E | F58: TITOLARE VALUE | G58: LOW COST 1ª FASCIA | H58: 98 | I58: =IFERROR(VLOOKUP(C58,'Lista calciatori'!$B$2:$AX$549,16,FALSE),"") | J58: 6 | K58: 7 | L58: =IFERROR(VLOOKUP(C58,'Lista calciatori'!$B$2:$AX$549,49,FALSE),"") | M58: =IFERROR(VLOOKUP(C58,'Lista calciatori'!$B$2:$AX$549,30,FALSE),"") | N58: =M58-L58 | O58: Ndaba | P58: =IFERROR(VLOOKUP(C58,'Lista calciatori'!$B$2:$AX$549,42,FALSE),"") | Q58: BASSO | R58: valore aumentato dalla possibile copertura di squadra/ruolo | S58: https://www.sosfanta.com/guida-asta-fantacalcio/fantacalcio-mantra-ecco-la-guida-allasta-2026-27-la-divisione-ruolo-per-ruolo/
A59: Ds | B59: 23 | C59: Marusic | D59: Lazio | E59: Dd/Ds/E | F59: LOW COST | G59: LOW COST 1ª FASCIA | H59: 60 | I59: =IFERROR(VLOOKUP(C59,'Lista calciatori'!$B$2:$AX$549,16,FALSE),"") | J59: 6 | K59: 12 | L59: =IFERROR(VLOOKUP(C59,'Lista calciatori'!$B$2:$AX$549,49,FALSE),"") | M59: =IFERROR(VLOOKUP(C59,'Lista calciatori'!$B$2:$AX$549,30,FALSE),"") | N59: =M59-L59 | O59: Pedraza | P59: =IFERROR(VLOOKUP(C59,'Lista calciatori'!$B$2:$AX$549,42,FALSE),"") | Q59: INFORTUNIO | R59: minuti a prezzo basso: utile per finanziare Pc/A | S59: https://www.sosfanta.com/guida-asta-fantacalcio/fantacalcio-mantra-ecco-la-guida-allasta-2026-27-la-divisione-ruolo-per-ruolo/
A60: Ds | B60: 24 | C60: Kamara H. | D60: Udinese | E60: Ds/E | F60: TITOLARE VALUE | G60: LOW COST 1ª FASCIA | H60: 98 | I60: =IFERROR(VLOOKUP(C60,'Lista calciatori'!$B$2:$AX$549,16,FALSE),"") | J60: 8 | K60: 6 | L60: =IFERROR(VLOOKUP(C60,'Lista calciatori'!$B$2:$AX$549,49,FALSE),"") | M60: =IFERROR(VLOOKUP(C60,'Lista calciatori'!$B$2:$AX$549,30,FALSE),"") | N60: =M60-L60 | O60: Arizala | P60: =IFERROR(VLOOKUP(C60,'Lista calciatori'!$B$2:$AX$549,42,FALSE),"") | Q60: BASSO | R60: valore aumentato dalla possibile copertura di squadra/ruolo | S60: https://www.sosfanta.com/guida-asta-fantacalcio/fantacalcio-mantra-ecco-la-guida-allasta-2026-27-la-divisione-ruolo-per-ruolo/
...

Sheet Coppie & Gioielli
A1: COPPIE, COPERTURE E GIOIELLI — COME FINANZIARE I TOP
A2: La coppia non significa necessariamente “riserva secca”: è una copertura di ruolo/gerarchia che riduce il rischio e consente di investire più crediti sugli slot decisivi.
A4: COPPIE / COPERTURE DA TENERE NEL MIRINO
A5: Priorita | B5: Squadra | C5: Titolare / primo nome | D5: R.Mantra | E5: Copertura | F5: R.Mantra | G5: Tipo | H5: Budget coppia indicativo | I5: Nota | J5: Fonte
A6: ALTA | B6: Roma | C6: Wesley | D6: E | E6: Rensch | F6: B/Dd/E | G6: copertura di fascia E/Dd | H6: 28-35 | I6: copertura di fascia, non handcuff puro finché gerarchia e condizione di Rensch non sono chiarite | J6: https://www.fantacalcio.it/probabili-formazioni-serie-a
A7: ALTA | B7: Milan | C7: Bartesaghi | D7: Ds/E | E7: Estupinan | F7: Ds/E | G7: ballottaggio/copertura Ds-E | H7: 12-18 | I7: se uno resta basso di prezzo, la coppia sterilizza il ballottaggio | J7: https://www.sosfanta.com/lista-formazioni/probabili-formazioni-serie-a/
A8: ALTA | B8: Napoli | C8: Spinazzola | D8: Ds/E | E8: Olivera | F8: B/Ds/E | G8: copertura Ds-E | H8: 15-20 | I8: utile se Spinazzola viene pagato da top ma Olivera resta low | J8: https://www.sosfanta.com/guida-asta-fantacalcio/fantacalcio-mantra-ecco-la-guida-allasta-2026-27-la-divisione-ruolo-per-ruolo/
A9: MEDIA | B9: Bologna | C9: Zortea | D9: Dd/E | E9: Holm | F9: Dd/E | G9: copertura Dd-E | H9: 12-16 | I9: buon modo per non pagare una seconda fascia premium | J9: https://www.sosfanta.com/guida-asta-fantacalcio/fantacalcio-mantra-ecco-la-guida-allasta-2026-27-la-divisione-ruolo-per-ruolo/
A10: MEDIA | B10: Atalanta | C10: Zappacosta | D10: Dd/E | E10: Bellanova | F10: Dd/E | G10: rotazione Dd-E | H10: 15-22 | I10: coppia più costosa: prendila solo se il secondo scivola | J10: https://www.sosfanta.com/guida-asta-fantacalcio/fantacalcio-mantra-ecco-la-guida-allasta-2026-27-la-divisione-ruolo-per-ruolo/
A11: MEDIA | B11: Napoli | C11: Di Lorenzo | D11: Dd/E | E11: Favasuli | F11: Dd/Ds/E | G11: copertura Dd-E | H11: 22-28 | I11: top + scommessa: struttura coerente con il piano | J11: https://www.sosfanta.com/guida-asta-fantacalcio/fantacalcio-mantra-ecco-la-guida-allasta-2026-27-la-divisione-ruolo-per-ruolo/
A12: MEDIA | B12: Parma | C12: Valeri | D12: Ds/E | E12: Britschgi | F12: Dd/Ds/E | G12: copertura Ds-E | H12: 8-12 | I12: provincia + pluriruolo: profilo da asta paziente | J12: https://www.sosfanta.com/guida-asta-fantacalcio/fantacalcio-mantra-ecco-la-guida-allasta-2026-27-la-divisione-ruolo-per-ruolo/
A13: MEDIA | B13: Roma | C13: Mancini | D13: Dc | E13: Koulierakis | F13: Dc | G13: Dc top + promessa | H13: 24-30 | I13: non una riserva secca: profondità con upside | J13: https://www.sosfanta.com/guida-asta-fantacalcio/fantacalcio-mantra-ecco-la-guida-allasta-2026-27-la-divisione-ruolo-per-ruolo/
A14: BASSA | B14: Inter | C14: Bastoni | D14: Dc | E14: Bisseck | F14: Dc | G14: profondita Dc | H14: 25-35 | I14: utile solo se Bisseck non viene rilanciato | J14: https://www.sosfanta.com/guida-asta-fantacalcio/fantacalcio-mantra-ecco-la-guida-allasta-2026-27-la-divisione-ruolo-per-ruolo/
A17: PACCHETTI PORTIERI — QUI LA COPPIA/TRIS È PARTE DELLA STRATEGIA
A18: Rank | B18: Squadra | C18: Titolare | D18: Riserve | E18: Cap pacchetto | F18: Target | G18: Qualita | H18: Mossa | I18: Nota | J18: Fonte
A19: 1 | B19: Roma | C19: Svilar | D19: Gollini + De Marzi | E19: 60 | F19: 55 | G19: SUPER TOP | H19: ATTACCA FINO A 55-60 | I19: coerente con storico lega; pacchetto chiuso | J19: https://www.sosfanta.com/guida-asta-fantacalcio/guida-asta-fantacalcio-2026-2027-tutti-consigli-fasce-chi-prendere/
A20: 2 | B20: Inter | C20: Martinez Jo. | D20: Provedel + Di Gennaro | E20: 58 | F20: 52 | G20: TOP | H20: ATTACCA | I20: Provedel può costare più del classico secondo | J20: https://www.sosfanta.com/guida-asta-fantacalcio/guida-asta-fantacalcio-2026-2027-tutti-consigli-fasce-chi-prendere/
A21: 3 | B21: Milan | C21: Maignan | D21: Terracciano + Torriani | E21: 55 | F21: 52 | G21: TOP | H21: ATTACCA | I21: porta affidabile; pacchetto semplice | J21: https://www.sosfanta.com/guida-asta-fantacalcio/guida-asta-fantacalcio-2026-2027-tutti-consigli-fasce-chi-prendere/
A22: 4 | B22: Juventus | C22: Vicario | D22: Perin + Di Gregorio* | E22: 60 | F22: 52 | G22: TOP | H22: ASPETTA MERCATO | I22: Vicario titolare; se Di Gregorio resta, costo/gerarchie da ricontrollare | J22: https://www.sosfanta.com/guida-asta-fantacalcio/guida-asta-fantacalcio-2026-2027-tutti-consigli-fasce-chi-prendere/
A23: 5 | B23: Atalanta | C23: Carnesecchi | D23: Sportiello + Vismara | E23: 53 | F23: 52 | G23: TOP | H23: COMPRA A VALORE | I23: titolare molto solido | J23: https://www.sosfanta.com/guida-asta-fantacalcio/guida-asta-fantacalcio-2026-2027-tutti-consigli-fasce-chi-prendere/
A24: 6 | B24: Como | C24: Butez | D24: Tornqvist + Vigorito | E24: 53 | F24: 52 | G24: TOP | H24: COMPRA A VALORE | I24: può costare meno per minore brand | J24: https://www.sosfanta.com/guida-asta-fantacalcio/guida-asta-fantacalcio-2026-2027-tutti-consigli-fasce-chi-prendere/
A25: 7 | B25: Napoli | C25: Meret | D25: Milinkovic-Savic V. + Contini | E25: 50 | F25: 50 | G25: SEMITOP | H25: SOLO PACCHETTO | I25: gerarchia più delicata: evita di prendere un solo nome | J25: https://www.sosfanta.com/guida-asta-fantacalcio/guida-asta-fantacalcio-2026-2027-tutti-consigli-fasce-chi-prendere/
A28: GIOIELLI / LOW COST — PROFILI DA 1-20 CREDITI CHE POSSONO FINANZIARE I TOP
A29: Ruolo | B29: Nome | C29: Squadra | D29: R.Mantra | E29: Tier | F29: Tit.% | G29: Prezzo obiettivo | H29: Offerta max | I29: Perché interessa | J29: Fonte
A30: Dc | B30: Ostigard | C30: Genoa | D30: Dc | E30: SOTTO AI SEMITOP | F30: 98 | G30: 7 | H30: 8 | I30: titolare/low cost da provincia; minutaggio forte | J30: https://www.sosfanta.com/guida-asta-fantacalcio/fantacalcio-mantra-ecco-la-guida-allasta-2026-27-la-divisione-ruolo-per-ruolo/
A31: Dc | B31: Dragusin | C31: Fiorentina | D31: Dc | E31: SOTTO AI SEMITOP | F31: 98 | G31: 7 | H31: 8 | I31: titolare/low cost da provincia; minutaggio forte | J31: https://www.sosfanta.com/guida-asta-fantacalcio/fantacalcio-mantra-ecco-la-guida-allasta-2026-27-la-divisione-ruolo-per-ruolo/
A32: Jolly | B32: Fazzini | C32: Cagliari | D32: C/T | E32: POSSIBILI SORPRESE | F32: 98 | G32: 11 | H32: 13 | I32: promessa segnalata; minutaggio forte | J32: https://www.sosfanta.com/guida-asta-fantacalcio/fantacalcio-mantra-ecco-la-guida-allasta-2026-27-la-divisione-ruolo-per-ruolo/
A33: C | B33: Fitz-Jim | C33: Torino | D33: M/C | E33: POSSIBILI SORPRESE | F33: 98 | G33: 5 | H33: 6 | I33: promessa segnalata; minutaggio forte | J33: https://www.sosfanta.com/guida-asta-fantacalcio/fantacalcio-mantra-ecco-la-guida-allasta-2026-27-la-divisione-ruolo-per-ruolo/
A34: Jolly | B34: Casadei | C34: Torino | D34: C/T | E34: POSSIBILI SORPRESE | F34: 82 | G34: 12 | H34: 14 | I34: promessa segnalata | J34: https://www.sosfanta.com/guida-asta-fantacalcio/fantacalcio-mantra-ecco-la-guida-allasta-2026-27-la-divisione-ruolo-per-ruolo/
A35: Jolly | B35: Baldanzi | C35: Genoa | D35: T | E35: POSSIBILI SORPRESE | F35: 82 | G35: 8 | H35: 10 | I35: promessa segnalata | J35: https://www.sosfanta.com/guida-asta-fantacalcio/fantacalcio-mantra-ecco-la-guida-allasta-2026-27-la-divisione-ruolo-per-ruolo/
A36: Dc | B36: Tiago Gabriel | C36: Lecce | D36: Dc | E36: FASCIA ALTA | F36: 98 | G36: 7 | H36: 8 | I36: titolare/low cost da provincia; minutaggio forte | J36: https://www.sosfanta.com/guida-asta-fantacalcio/fantacalcio-mantra-ecco-la-guida-allasta-2026-27-la-divisione-ruolo-per-ruolo/
A37: Jolly | B37: Diouf | C37: Inter | D37: E/C | E37: POSSIBILI SORPRESE | F37: 82 | G37: 12 | H37: 14 | I37: promessa segnalata | J37: https://www.sosfanta.com/guida-asta-fantacalcio/fantacalcio-mantra-ecco-la-guida-allasta-2026-27-la-divisione-ruolo-per-ruolo/
A38: Dc | B38: Scalvini | C38: Atalanta | D38: Dc | E38: FASCIA ALTA | F38: 98 | G38: 7 | H38: 8 | I38: titolare/low cost da provincia; minutaggio forte | J38: https://www.sosfanta.com/guida-asta-fantacalcio/fantacalcio-mantra-ecco-la-guida-allasta-2026-27-la-divisione-ruolo-per-ruolo/
A39: Dc | B39: Mina | C39: Cagliari | D39: Dc | E39: FASCIA ALTA | F39: 94 | G39: 7 | H39: 8 | I39: titolare/low cost da provincia; minutaggio forte | J39: https://www.sosfanta.com/guida-asta-fantacalcio/fantacalcio-mantra-ecco-la-guida-allasta-2026-27-la-divisione-ruolo-per-ruolo/
A40: C | B40: Oulai | C40: Fiorentina | D40: M/C | E40: POSSIBILI SORPRESE | F40: 75 | G40: 6 | H40: 7 | I40: promessa segnalata | J40: https://www.sosfanta.com/guida-asta-fantacalcio/fantacalcio-mantra-ecco-la-guida-allasta-2026-27-la-divisione-ruolo-per-ruolo/
A41: Dd | B41: Norton-Cuffy | C41: Genoa | D41: Dd/E | E41: LOW COST 1ª FASCIA | F41: 98 | G41: 13 | H41: 15 | I41: titolare/low cost da provincia; minutaggio forte | J41: https://www.sosfanta.com/guida-asta-fantacalcio/fantacalcio-mantra-ecco-la-guida-allasta-2026-27-la-divisione-ruolo-per-ruolo/
... A69: Dd | B69: Birindelli | C69: Monza | D69: Dd/Ds/E | E69: LOW COST 1ª FASCIA | F69: 82 | G69: 7 | H69: 8 | I69: titolare/low cost da provincia | J69: https://www.sosfanta.com/guida-asta-fantacalcio/fantacalcio-mantra-ecco-la-guida-allasta-2026-27-la-divisione-ruolo-per-ruolo/

Sheet Dashboard
A1: DASHBOARD ASTA MANTRA — 4-3-3 BOMBER + GIOIELLI
A2: 12 squadre | 500 crediti | prezzi tarati sullo storico della lega | strategia: pagare davvero 1-2 stelle e finanziare con titolari value, scommesse e coppie.
A4: BUDGET | C4: A + Pc | E4: MOVIMENTO | G4: PORTIERI
A5: 500 | C5: 272 | E5: 448 | G5: 52
A7: crediti | C7: 54,4% budget | E7: target | G7: target pacchetto
A9: BUDGET PER REPARTO | F9: PRIORITA OPERATIVE
A10: Reparto | B10: Slot | C10: Target | D10: % budget | F10: 1 | G10: Pc | H10: 145 target, 160+ cap sui supertop
A11: Por | B11: 3 | C11: 52 | D11: =C11/$A$100 | F11: 2 | G11: A | H11: 1 top vero: target 65, cap 85
A12: Dd | B12: 3 | C12: 24 | D12: =C12/$A$100 | F12: 3 | G12: Portieri | H12: pacchetto top 50-60 è accettabile
A13: Ds | B13: 3 | C13: 24 | D13: =C13/$A$100 | F13: 4 | G13: C/M | H13: bonus e titolarità, ma evita guerre
A14: Dc | B14: 5 | C14: 30 | D14: =C14/$A$100 | F14: 5 | G14: Dd/Ds | H14: un premium per lato solo se finanziabile
A15: Jolly | B15: 2 | C15: 8 | D15: =C15/$A$100 | F15: 6 | G15: Dc/Jolly | H15: zona di recupero crediti e coppie
A16: A | B16: 4 | C16: 100 | D16: =C16/$A$100
A17: C | B17: 3 | C17: 48 | D17: =C17/$A$100
A18: M | B18: 3 | C18: 42 | D18: =C18/$A$100
A19: Pc | B19: 2 | C19: 172 | D19: =C19/$A$100
A21: TARGET PRINCIPALI — PROFILI SOSTENIBILI, NON CLASSIFICA ASSOLUTA
A22: Dd | B22: Kalulu / Di Lorenzo / Cambiaso | F22: cap top 35-40, ma target slot 18
A23: Ds | B23: Jimenez / Spinazzola / Cambiaso | F23: top sì, non obbligatorio pagarlo 35
A24: Dc | B24: Bremer / Bastoni / Mancini / Solet | F24: 20-23 è coerente; poi low cost
A25: A | B25: Paz / Orsolini / Pulisic / Yildiz | F25: 65-80 realistici sui top
A26: C | B26: McTominay / Atta / Da Cunha / Barella | F26: priorità ai profili offensivi
A27: M | B27: Ederson / Modric / Konè / Perrone | F27: 3 titolari, non servono 3 nomi premium
A28: Pc | B28: Malen / Lautaro / Hojlund / Ramos / Kolo | F28: bomber: 130-160 realistico
A29: Gioielli | B29: vedi foglio Coppie & Gioielli | F29: 10 slot da pochi crediti finanziano le stelle
A32: ATTENZIONE CALENDARIO
A33: Il file e aggiornato alla mattina del 28/08, ma non puo essere ancora "post mercato": la finestra Serie A chiude il 1 settembre alle 20:00. Fantacalcio ha annunciato un check finale dei ruoli Mantra il 2 settembre, solo espansivo (puo aggiungere un ruolo, non toglierlo).
A100: 500

Sheet Lista calciatori
A1: # | B1: Nome | C1: Fuori lista | D1: Sq. | E1: Under | F1: R. | G1: R.MANTRA | H1: PGv | I1: MV | J1: FM | K1: FVM (scala 500) | L1: QUOT. | M1: FantaSquadra | N1: Costo | O1: Titolarità % | P1: Classe tit. | Q1: Indice Fanta | R1: Indice Affare | S1: Fascia | T1: Mia mossa | U1: Priorità 1-5 | V1: Rischio | W1: Versatilità | X1: Tier SOS | Y1: Affidabilità | Z1: Motivo sintetico | AA1: Fonte titolarità | AB1: Fonte Mantra | AC1: Fonte update | AD1: Stato asta | AE1: Offerta max | AF1: Note asta | AG1: H_TitBase | AH1: H_TitAdj | AI1: H_SOSScore | AJ1: H_FVMpct | AK1: H_Perf | AL1: H_SeasonMatch | AM1: H_SOSMatch | AN1: H_CurrentMatch | AO1: Prezzo atteso lega 12x500 | AP1: Fit 4-3-3 | AQ1: Strategia 4-3-3 | AR1: Famiglia 4-3-3 | AS1: Tier gruppo | AT1: Fattore rischio | AU1: Moltiplicatore asta storico | AV1: Walk-away cap ruolo | AW1: Fonte prezzo | AX1: Prezzo obiettivo
A2: 5585 | B2: Malen | D2: Roma | E2: 27 | F2: A | G2: Pc | H2: 1 | I2: 8.5 | J2: 17.5 | K2: 207 | L2: 36 | O2: =MAX(0,MIN(99,AG2+AH2)) | P2: =IF(O2>=80,"Alta",IF(O2>=60,"Medio-alta",IF(O2>=40,"Media",IF(O2>=20,"Bassa","Minima")))) | Q2: =MAX(5,MIN(99,ROUND(IF(AI2>0,0.5*AI2+0.25*AJ2+0.2*O2+0.05*AK2,0.55*AJ2+0.32*O2+0.08*AK2+0.05*MIN(100,L2*4))+MIN(6,(LEN(G2)-LEN(SUBSTITUTE(G2,"/","")))*2.5)-IF(C2="*",3,0),0))) | R2: =MAX(5,MIN(99,ROUND(50+0.65*(Q2-50)+0.2*(O2-60)-0.55*(AJ2-50),0))) | S2: =IF(Q2>=90,"S",IF(Q2>=80,"A",IF(Q2>=70,"B",IF(Q2>=60,"C",IF(Q2>=48,"D","E"))))) | T2: =IF(AND(Q2>=90,O2>=62),"PUNTA FORTE",IF(AND(Q2>=80,O2>=58),"COMPRA",IF(AND(R2>=75,Q2>=62,O2>=55),"AFFARE / ATTACCA",IF(AND(Q2>=69,O2>=50),"AL GIUSTO PREZZO",IF(AND(Q2>=58,O2>=40),"JOLLY / SCOMMESSA",IF(Q2>=45,"SOLO LOW COST","EVITA")))))) | U2: 5 | V2: BASSO | W2: =LEN(G2)-LEN(SUBSTITUTE(G2,"/",""))+1 | X2: SUPER TOP | Y2: =IF(AL2+AM2+AN2>=3,"Alta",IF(AL2+AM2+AN2>=2,"Medio-alta",IF(AL2+AM2+AN2=1,"Media","Bassa"))) | Z2: XI base; SOS: super top | AA2: https://www.fantacalcio.it/news/calcio-italia/06_08_2026/asta-fantacalcio-le-probabili-formazioni-della-serie-a-enilive-2026-27-495558 | https://www.fantacalcio.it/probabili-formazioni-serie-a | AB2: https://www.sosfanta.com/guida-asta-fantacalcio/fantacalcio-mantra-ecco-la-guida-allasta-2026-27-la-divisione-ruolo-per-ruolo/ | AC2: https://www.fantacalcio.it/probabili-formazioni-serie-a | https://www.fantacalcio.it/quotazioni-fantacalcio | AD2: Da valutare | AE2: =MAX(1,MIN(AV2,ROUND(AO2*1.06,0))) | AG2: 98 | AH2: 0 | AI2: 98 | AJ2: 99.5 | AK2: 100 | AL2: 1 | AM2: 1 | AN2: 1 | AO2: =MAX(1,ROUND(L2*AU2*AT2*IF(ISNUMBER(SEARCH("SUPER TOP",X2&"")),1.08,IF(AS2="Top",1.04,IF(AS2="Semitop",1,IF(AS2="Starter",0.94,IF(AS2="Scommessa",0.9,0.85))))),0)) | AP2: =IF(AR2="Non433","BASSO",IF(OR(AR2="A",AR2="Pc"),"ALTISSIMO",IF(OR(AR2="M",AR2="C",AR2="Jolly"),"ALTO",IF(OR(AR2="Dd",AR2="Ds"),"MEDIO-ALTO","MEDIO")))) | AQ2: =IF(C2="*","EVITA - FUORI LISTA",IF(AR2="Non433","NON PRIORITARIO 4-3-3",IF(AND(OR(AR2="Pc",AR2="A"),AS2="Top"),"ALL-IN CONTROLLATO",IF(AND(AE2<=8,O2>=80),"GIOIELLO / TITOLARE LOW COST",IF(OR(AS2="Top",AS2="Semitop"),"COMPRA A VALORE",IF(O2>=80,"TITOLARE DA ASPETTARE","SOLO LOW COST")))))) | AR2: =IF(G2="Por","Por",IF(ISNUMBER(SEARCH("/Pc/","/"&G2&"/")),"Pc",IF(ISNUMBER(SEARCH("/A/","/"&G2&"/")),"A",IF(ISNUMBER(SEARCH("/M/","/"&G2&"/")),"M",IF(ISNUMBER(SEARCH("/C/","/"&G2&"/")),"C",IF(ISNUMBER(SEARCH("/Dd/","/"&G2&"/")),"Dd",IF(ISNUMBER(SEARCH("/Ds/","/"&G2&"/")),"Ds",IF(ISNUMBER(SEARCH("/Dc/","/"&G2&"/")),"Dc",IF(OR(ISNUMBER(SEARCH("/E/","/"&G2&"/")),ISNUMBER(SEARCH("/W/","/"&G2&"/")),ISNUMBER(SEARCH("/T/","/"&G2&"/")),ISNUMBER(SEARCH("/B/","/"&G2&"/"))),"Jolly","Non433"))))))))) | AS2: =IF(OR(X2="SUPER TOP",X2="TOP"),"Top",IF(X2="SEMITOP","Semitop",IF(OR(ISNUMBER(SEARCH("POSSIBILI SORPRESE",X2&"")),ISNUMBER(SEARCH("SCOMMES",X2&""))),"Scommessa",IF(OR(ISNUMBER(SEARCH("FASCIA ALTA",X2&"")),ISNUMBER(SEARCH("JOLLY 1",X2&"")),O2>=85),"Starter",IF(O2>=68,"Scommessa","Low"))))) | AT2: =IF(O2>=90,1,IF(O2>=80,0.93,IF(O2>=65,0.85,0.72)))*IF(ISNUMBER(SEARCH("MERCATO",V2&"")),0.85,1)*IF(ISNUMBER(SEARCH("INFORTUN",V2&"")),0.9,1)*IF(C2="*",0.55,1) | AU2: =IFERROR(VLOOKUP(AR2,'Strategia 433'!$A$29:$B$38,2,FALSE),0.9) | AV2: =IFERROR(INDEX('Strategia 433'!$D$15:$H$24,MATCH(AR2,'Strategia 433'!$A$15:$A$24,0),MATCH(AS2,'Strategia 433'!$D$14:$H$14,0))*IF(AND(ISNUMBER(SEARCH("SUPER TOP",X2&"")),OR(AR2="Por",AR2="Pc")),1.08,1),1) | AW2: Taratura storico lega 12x500 + QUOT Fantacalcio | https://www.fantacalcio.it/quotazioni-fantacalcio | AX2: =MAX(1,ROUND(AE2*IF(AND(AR2="Pc",AS2="Top"),0.95,IF(AND(OR(AR2="A",AR2="Por",AR2="Dc"),AS2="Top"),0.90,0.85)),0))
A3: 2764 | B3: Martinez L. | D3: Inter | E3: 29 | F3: A | G3: Pc | H3: 1 | I3: 5.5 | J3: 5 | K3: 184 | L3: 34 | O3: =MAX(0,MIN(99,AG3+AH3)) | P3: =IF(O3>=80,"Alta",IF(O3>=60,"Medio-alta",IF(O3>=40,"Media",IF(O3>=20,"Bassa","Minima")))) | Q3: =MAX(5,MIN(99,ROUND(IF(AI3>0,0.5*AI3+0.25*AJ3+0.2*O3+0.05*AK3,0.55*AJ3+0.32*O3+0.08*AK3+0.05*MIN(100,L3*4))+MIN(6,(LEN(G3)-LEN(SUBSTITUTE(G3,"/","")))*2.5)-IF(C3="*",3,0),0))) | R3: =MAX(5,MIN(99,ROUND(50+0.65*(Q3-50)+0.2*(O3-60)-0.55*(AJ3-50),0))) | S3: =IF(Q3>=90,"S",IF(Q3>=80,"A",IF(Q3>=70,"B",IF(Q3>=60,"C",IF(Q3>=48,"D","E"))))) | T3: =IF(AND(Q3>=90,O3>=62),"PUNTA FORTE",IF(AND(Q3>=80,O3>=58),"COMPRA",IF(AND(R3>=75,Q3>=62,O3>=55),"AFFARE / ATTACCA",IF(AND(Q3>=69,O3>=50),"AL GIUSTO PREZZO",IF(AND(Q3>=58,O3>=40),"JOLLY / SCOMMESSA",IF(Q3>=45,"SOLO LOW COST","EVITA")))))) | U3: 5 | V3: BASSO | W3: =LEN(G3)-LEN(SUBSTITUTE(G3,"/",""))+1 | X3: SUPER TOP | Y3: =IF(AL3+AM3+AN3>=3,"Alta",IF(AL3+AM3+AN3>=2,"Medio-alta",IF(AL3+AM3+AN3=1,"Media","Bassa"))) | Z3: XI base; SOS: super top | AA3: https://www.fantacalcio.it/news/calcio-italia/06_08_2026/asta-fantacalcio-le-probabili-formazioni-della-serie-a-enilive-2026-27-495558 | https://www.fantacalcio.it/probabili-formazioni-serie-a | AB3: https://www.sosfanta.com/guida-asta-fantacalcio/fantacalcio-mantra-ecco-la-guida-allasta-2026-27-la-divisione-ruolo-per-ruolo/ | AC3: https://www.fantacalcio.it/probabili-formazioni-serie-a | https://www.fantacalcio.it/quotazioni-fantacalcio | AD3: Da valutare | AE3: =MAX(1,MIN(AV3,ROUND(AO3*1.06,0))) | AG3: 98 | AH3: 0 | AI3: 98 | AJ3: 98.4 | AK3: 32 | AL3: 1 | AM3: 1 | AN3: 1 | AO3: =MAX(1,ROUND(L3*AU3*AT3*IF(ISNUMBER(SEARCH("SUPER TOP",X3&"")),1.08,IF(AS3="Top",1.04,IF(AS3="Semitop",1,IF(AS3="Starter",0.94,IF(AS3="Scommessa",0.9,0.85))))),0)) | AP3: =IF(AR3="Non433","BASSO",IF(OR(AR3="A",AR3="Pc"),"ALTISSIMO",IF(OR(AR3="M",AR3="C",AR3="Jolly"),"ALTO",IF(OR(AR3="Dd",AR3="Ds"),"MEDIO-ALTO","MEDIO")))) | AQ3: =IF(C3="*","EVITA - FUORI LISTA",IF(AR3="Non433","NON PRIORITARIO 4-3-3",IF(AND(OR(AR3="Pc",AR3="A"),AS3="Top"),"ALL-IN CONTROLLATO",IF(AND(AE3<=8,O3>=80),"GIOIELLO / TITOLARE LOW COST",IF(OR(AS3="Top",AS3="Semitop"),"COMPRA A VALORE",IF(O3>=80,"TITOLARE DA ASPETTARE","SOLO LOW COST")))))) | AR3: =IF(G3="Por","Por",IF(ISNUMBER(SEARCH("/Pc/","/"&G3&"/")),"Pc",IF(ISNUMBER(SEARCH("/A/","/"&G3&"/")),"A",IF(ISNUMBER(SEARCH("/M/","/"&G3&"/")),"M",IF(ISNUMBER(SEARCH("/C/","/"&G3&"/")),"C",IF(ISNUMBER(SEARCH("/Dd/","/"&G3&"/")),"Dd",IF(ISNUMBER(SEARCH("/Ds/","/"&G3&"/")),"Ds",IF(ISNUMBER(SEARCH("/Dc/","/"&G3&"/")),"Dc",IF(OR(ISNUMBER(SEARCH("/E/","/"&G3&"/")),ISNUMBER(SEARCH("/W/","/"&G3&"/")),ISNUMBER(SEARCH("/T/","/"&G3&"/")),ISNUMBER(SEARCH("/B/","/"&G3&"/"))),"Jolly","Non433"))))))))) | AS3: =IF(OR(X3="SUPER TOP",X3="TOP"),"Top",IF(X3="SEMITOP","Semitop",IF(OR(ISNUMBER(SEARCH("POSSIBILI SORPRESE",X3&"")),ISNUMBER(SEARCH("SCOMMES",X3&""))),"Scommessa",IF(OR(ISNUMBER(SEARCH("FASCIA ALTA",X3&"")),ISNUMBER(SEARCH("JOLLY 1",X3&"")),O3>=85),"Starter",IF(O3>=68,"Scommessa","Low"))))) | AT3: =IF(O3>=90,1,IF(O3>=80,0.93,IF(O3>=65,0.85,0.72)))*IF(ISNUMBER(SEARCH("MERCATO",V3&"")),0.85,1)*IF(ISNUMBER(SEARCH("INFORTUN",V3&"")),0.9,1)*IF(C3="*",0.55,1) | AU3: =IFERROR(VLOOKUP(AR3,'Strategia 433'!$A$29:$B$38,2,FALSE),0.9) | AV3: =IFERROR(INDEX('Strategia 433'!$D$15:$H$24,MATCH(AR3,'Strategia 433'!$A$15:$A$24,0),MATCH(AS3,'Strategia 433'!$D$14:$H$14,0))*IF(AND(ISNUMBER(SEARCH("SUPER TOP",X3&"")),OR(AR3="Por",AR3="Pc")),1.08,1),1) | AW3: Taratura storico lega 12x500 + QUOT Fantacalcio | https://www.fantacalcio.it/quotazioni-fantacalcio | AX3: =MAX(1,ROUND(AE3*IF(AND(AR3="Pc",AS3="Top"),0.95,IF(AND(OR(AR3="A",AR3="Por",AR3="Dc"),AS3="Top"),0.90,0.85)),0))
